<mujoco model="dual_ur5e_official_0330"><compiler angle="radian" meshdir="D:\Michael\2025\01.Research\01.Parceldetection\16.Pybullet\mujoco_menagerie\universal_robots_ur5e\assets" autolimits="true" /><option integrator="implicitfast" timestep="0.002" gravity="0 0 -9.81" /><size memory="128M" nconmax="2000" /><statistic center="0.45 0 0.45" extent="1.2" /><visual><headlight diffuse="0.6 0.6 0.6" ambient="0.1 0.1 0.1" specular="0 0 0" /><rgba haze="0.15 0.25 0.35 1" /><global azimuth="120" elevation="-20" /></visual><asset>
    <material class="ur5e" name="black" rgba="0.033 0.033 0.033 1" />
    <material class="ur5e" name="jointgray" rgba="0.278 0.278 0.278 1" />
    <material class="ur5e" name="linkgray" rgba="0.82 0.82 0.82 1" />
    <material class="ur5e" name="urblue" rgba="0.49 0.678 0.8 1" />

    <mesh file="base_0.obj" />
    <mesh file="base_1.obj" />
    <mesh file="shoulder_0.obj" />
    <mesh file="shoulder_1.obj" />
    <mesh file="shoulder_2.obj" />
    <mesh file="upperarm_0.obj" />
    <mesh file="upperarm_1.obj" />
    <mesh file="upperarm_2.obj" />
    <mesh file="upperarm_3.obj" />
    <mesh file="forearm_0.obj" />
    <mesh file="forearm_1.obj" />
    <mesh file="forearm_2.obj" />
    <mesh file="forearm_3.obj" />
    <mesh file="wrist1_0.obj" />
    <mesh file="wrist1_1.obj" />
    <mesh file="wrist1_2.obj" />
    <mesh file="wrist2_0.obj" />
    <mesh file="wrist2_1.obj" />
    <mesh file="wrist2_2.obj" />
    <mesh file="wrist3.obj" />
  </asset>

  <default>
    <default class="ur5e">
      <material specular="0.5" shininess="0.25" />
      <joint axis="0 1 0" range="-6.28319 6.28319" armature="0.1" />
      <general gaintype="fixed" biastype="affine" ctrlrange="-6.2831 6.2831" gainprm="2000" biasprm="0 -2000 -400" forcerange="-150 150" />
      <default class="size3">
        <default class="size3_limited">
          <joint range="-3.1415 3.1415" />
          <general ctrlrange="-3.1415 3.1415" />
        </default>
      </default>
      <default class="size1">
        <general gainprm="500" biasprm="0 -500 -100" forcerange="-28 28" />
      </default>
      <default class="visual">
        <geom type="mesh" contype="0" conaffinity="0" group="2" />
      </default>
      <default class="collision">
        <geom type="capsule" group="3" />
        <default class="eef_collision">
          <geom type="cylinder" />
        </default>
      </default>
      <site size="0.001" rgba="0.5 0.5 0.5 0.3" group="4" />
    </default>
  </default>

  <worldbody><light name="main_light" pos="0 0 1.8" dir="0 0 -1" directional="true" /><geom name="floor" type="plane" size="0 0 0.05" rgba="0.92 0.92 0.92 1" /><camera name="overview" pos="1.6 0 1.0" xyaxes="0 1 0 -0.40 0 0.92" /><body name="left_base" quat="0 0 0 -1" childclass="ur5e" pos="0.000000 -0.450000 0.000000">
      <inertial mass="4.0" pos="0 0 0" diaginertia="0.00443333156 0.00443333156 0.0072" />
      <geom mesh="base_0" material="black" class="visual" />
      <geom mesh="base_1" material="jointgray" class="visual" />
      <body name="left_shoulder_link" pos="0 0 0.163">
        <inertial mass="3.7" pos="0 0 0" diaginertia="0.0102675 0.0102675 0.00666" />
        <joint name="left_shoulder_pan_joint" class="size3" axis="0 0 1" />
        <geom mesh="shoulder_0" material="urblue" class="visual" />
        <geom mesh="shoulder_1" material="black" class="visual" />
        <geom mesh="shoulder_2" material="jointgray" class="visual" />
        <geom class="collision" size="0.06 0.06" pos="0 0 -0.04" />
        <body name="left_upper_arm_link" pos="0 0.138 0" quat="1 0 1 0">
          <inertial mass="8.393" pos="0 0 0.2125" diaginertia="0.133886 0.133886 0.0151074" />
          <joint name="left_shoulder_lift_joint" class="size3" />
          <geom mesh="upperarm_0" material="linkgray" class="visual" />
          <geom mesh="upperarm_1" material="black" class="visual" />
          <geom mesh="upperarm_2" material="jointgray" class="visual" />
          <geom mesh="upperarm_3" material="urblue" class="visual" />
          <geom class="collision" pos="0 -0.04 0" quat="1 1 0 0" size="0.06 0.06" />
          <geom class="collision" size="0.05 0.2" pos="0 0 0.2" />
          <body name="left_forearm_link" pos="0 -0.131 0.425">
            <inertial mass="2.275" pos="0 0 0.196" diaginertia="0.0311796 0.0311796 0.004095" />
            <joint name="left_elbow_joint" class="size3_limited" />
            <geom mesh="forearm_0" material="urblue" class="visual" />
            <geom mesh="forearm_1" material="linkgray" class="visual" />
            <geom mesh="forearm_2" material="black" class="visual" />
            <geom mesh="forearm_3" material="jointgray" class="visual" />
            <geom class="collision" pos="0 0.08 0" quat="1 1 0 0" size="0.055 0.06" />
            <geom class="collision" size="0.038 0.19" pos="0 0 0.2" />
            <body name="left_wrist_1_link" pos="0 0 0.392" quat="1 0 1 0">
              <inertial mass="1.219" pos="0 0.127 0" diaginertia="0.0025599 0.0025599 0.0021942" />
              <joint name="left_wrist_1_joint" class="size1" />
              <geom mesh="wrist1_0" material="black" class="visual" />
              <geom mesh="wrist1_1" material="urblue" class="visual" />
              <geom mesh="wrist1_2" material="jointgray" class="visual" />
              <geom class="collision" pos="0 0.05 0" quat="1 1 0 0" size="0.04 0.07" />
              <body name="left_wrist_2_link" pos="0 0.127 0">
                <inertial mass="1.219" pos="0 0 0.1" diaginertia="0.0025599 0.0025599 0.0021942" />
                <joint name="left_wrist_2_joint" axis="0 0 1" class="size1" />
                <geom mesh="wrist2_0" material="black" class="visual" />
                <geom mesh="wrist2_1" material="urblue" class="visual" />
                <geom mesh="wrist2_2" material="jointgray" class="visual" />
                <geom class="collision" size="0.04 0.06" pos="0 0 0.04" />
                <geom class="collision" pos="0 0.02 0.1" quat="1 1 0 0" size="0.04 0.04" />
                <body name="left_wrist_3_link" pos="0 0 0.1">
                  <inertial mass="0.1889" pos="0 0.0771683 0" quat="1 0 0 1" diaginertia="0.000132134 9.90863e-05 9.90863e-05" />
                  <joint name="left_wrist_3_joint" class="size1" />
                  <geom material="linkgray" mesh="wrist3" class="visual" />
                  <geom class="eef_collision" pos="0 0.08 0" quat="1 1 0 0" size="0.04 0.02" />
                  <site name="left_attachment_site" pos="0 0.1 0" quat="-1 1 0 0" />
                </body>
              </body>
            </body>
          </body>
        </body>
      </body>
    </body>
  <body name="right_base" quat="0 0 0 -1" childclass="ur5e" pos="0.000000 0.450000 0.000000">
      <inertial mass="4.0" pos="0 0 0" diaginertia="0.00443333156 0.00443333156 0.0072" />
      <geom mesh="base_0" material="black" class="visual" />
      <geom mesh="base_1" material="jointgray" class="visual" />
      <body name="right_shoulder_link" pos="0 0 0.163">
        <inertial mass="3.7" pos="0 0 0" diaginertia="0.0102675 0.0102675 0.00666" />
        <joint name="right_shoulder_pan_joint" class="size3" axis="0 0 1" />
        <geom mesh="shoulder_0" material="urblue" class="visual" />
        <geom mesh="shoulder_1" material="black" class="visual" />
        <geom mesh="shoulder_2" material="jointgray" class="visual" />
        <geom class="collision" size="0.06 0.06" pos="0 0 -0.04" />
        <body name="right_upper_arm_link" pos="0 0.138 0" quat="1 0 1 0">
          <inertial mass="8.393" pos="0 0 0.2125" diaginertia="0.133886 0.133886 0.0151074" />
          <joint name="right_shoulder_lift_joint" class="size3" />
          <geom mesh="upperarm_0" material="linkgray" class="visual" />
          <geom mesh="upperarm_1" material="black" class="visual" />
          <geom mesh="upperarm_2" material="jointgray" class="visual" />
          <geom mesh="upperarm_3" material="urblue" class="visual" />
          <geom class="collision" pos="0 -0.04 0" quat="1 1 0 0" size="0.06 0.06" />
          <geom class="collision" size="0.05 0.2" pos="0 0 0.2" />
          <body name="right_forearm_link" pos="0 -0.131 0.425">
            <inertial mass="2.275" pos="0 0 0.196" diaginertia="0.0311796 0.0311796 0.004095" />
            <joint name="right_elbow_joint" class="size3_limited" />
            <geom mesh="forearm_0" material="urblue" class="visual" />
            <geom mesh="forearm_1" material="linkgray" class="visual" />
            <geom mesh="forearm_2" material="black" class="visual" />
            <geom mesh="forearm_3" material="jointgray" class="visual" />
            <geom class="collision" pos="0 0.08 0" quat="1 1 0 0" size="0.055 0.06" />
            <geom class="collision" size="0.038 0.19" pos="0 0 0.2" />
            <body name="right_wrist_1_link" pos="0 0 0.392" quat="1 0 1 0">
              <inertial mass="1.219" pos="0 0.127 0" diaginertia="0.0025599 0.0025599 0.0021942" />
              <joint name="right_wrist_1_joint" class="size1" />
              <geom mesh="wrist1_0" material="black" class="visual" />
              <geom mesh="wrist1_1" material="urblue" class="visual" />
              <geom mesh="wrist1_2" material="jointgray" class="visual" />
              <geom class="collision" pos="0 0.05 0" quat="1 1 0 0" size="0.04 0.07" />
              <body name="right_wrist_2_link" pos="0 0.127 0">
                <inertial mass="1.219" pos="0 0 0.1" diaginertia="0.0025599 0.0025599 0.0021942" />
                <joint name="right_wrist_2_joint" axis="0 0 1" class="size1" />
                <geom mesh="wrist2_0" material="black" class="visual" />
                <geom mesh="wrist2_1" material="urblue" class="visual" />
                <geom mesh="wrist2_2" material="jointgray" class="visual" />
                <geom class="collision" size="0.04 0.06" pos="0 0 0.04" />
                <geom class="collision" pos="0 0.02 0.1" quat="1 1 0 0" size="0.04 0.04" />
                <body name="right_wrist_3_link" pos="0 0 0.1">
                  <inertial mass="0.1889" pos="0 0.0771683 0" quat="1 0 0 1" diaginertia="0.000132134 9.90863e-05 9.90863e-05" />
                  <joint name="right_wrist_3_joint" class="size1" />
                  <geom material="linkgray" mesh="wrist3" class="visual" />
                  <geom class="eef_collision" pos="0 0.08 0" quat="1 1 0 0" size="0.04 0.02" />
                  <site name="right_attachment_site" pos="0 0.1 0" quat="-1 1 0 0" />
                </body>
              </body>
            </body>
          </body>
        </body>
      </body>
    </body>
  </worldbody><actuator><general class="size3" name="left_shoulder_pan" joint="left_shoulder_pan_joint" />
    <general class="size3" name="left_shoulder_lift" joint="left_shoulder_lift_joint" />
    <general class="size3_limited" name="left_elbow" joint="left_elbow_joint" />
    <general class="size1" name="left_wrist_1" joint="left_wrist_1_joint" />
    <general class="size1" name="left_wrist_2" joint="left_wrist_2_joint" />
    <general class="size1" name="left_wrist_3" joint="left_wrist_3_joint" />
  <general class="size3" name="right_shoulder_pan" joint="right_shoulder_pan_joint" />
    <general class="size3" name="right_shoulder_lift" joint="right_shoulder_lift_joint" />
    <general class="size3_limited" name="right_elbow" joint="right_elbow_joint" />
    <general class="size1" name="right_wrist_1" joint="right_wrist_1_joint" />
    <general class="size1" name="right_wrist_2" joint="right_wrist_2_joint" />
    <general class="size1" name="right_wrist_3" joint="right_wrist_3_joint" />
  </actuator></mujoco>