<mujoco model="ctrl_bar_check">
  <compiler angle="radian" coordinate="local" inertiafromgeom="true" meshdir="D:/Michael/2025/01.Research/01.Parceldetection/16.Pybullet/bullet3-master (1)/bullet3-master/examples/pybullet/examples/DeformableTest/Sackcodex2/object"/>
  <option timestep="0.002" gravity="0 0 -9.81" integrator="implicitfast" iterations="100" tolerance="1e-8"/>
  <size memory="768M" nconmax="12000"/>

  <visual>
    <global azimuth="128" elevation="-20"/>
    <headlight ambient="0.34 0.34 0.34" diffuse="0.78 0.78 0.78" specular="0.15 0.15 0.15"/>
    <rgba haze="0.11 0.13 0.18 1"/>
  </visual>

  <default>
    <geom condim="4" friction="1.15 0.03 0.01" margin="0.003" solimp="0.93 0.98 0.003" solref="0.012 1"/>
    <joint damping="1.2" armature="0.002"/>
    <position kp="2500" forcelimited="true" forcerange="-420 420"/>
    <motor ctrllimited="true"/>
  </default>

  <asset>
    <mesh name="sack_0_visual_mesh" file="sack9.obj" scale="0.0670 0.0670 0.0708"/>
    <mesh name="sack_1_visual_mesh" file="sack2.obj" scale="0.0742 0.0742 0.0783"/>
    <mesh name="sack_2_visual_mesh" file="sack6Apply.obj" scale="0.0679 0.0679 0.0698"/>
    <mesh name="sack_3_visual_mesh" file="sack9.obj" scale="0.0700 0.0700 0.0775"/>
    <mesh name="sack_4_visual_mesh" file="sack.obj" scale="0.0664 0.0664 0.0691"/>
  </asset>

  <worldbody>
    <light name="key" pos="0.85 0.15 1.8" dir="-0.2 -0.1 -1" directional="true"/>
    <geom name="floor" type="plane" size="2 2 0.1" rgba="0.93 0.93 0.93 1"/>
    <geom name="work_pad" type="box" pos="0.62 0 0.012" size="0.30 0.30 0.012" rgba="0.60 0.61 0.62 1" friction="1.4 0.05 0.01"/>
    <geom name="corral_front" type="box" pos="0.93 0.00 0.08" size="0.010 0.30 0.08" rgba="0.55 0.55 0.58 0.22" friction="1.0 0.03 0.01"/>
    <geom name="corral_back" type="box" pos="0.31 0.00 0.08" size="0.010 0.30 0.08" rgba="0.55 0.55 0.58 0.18" friction="1.0 0.03 0.01"/>
    <geom name="corral_left" type="box" pos="0.62 0.30 0.08" size="0.30 0.010 0.08" rgba="0.55 0.55 0.58 0.14" friction="1.0 0.03 0.01"/>
    <geom name="corral_right" type="box" pos="0.62 -0.30 0.08" size="0.30 0.010 0.08" rgba="0.55 0.55 0.58 0.14" friction="1.0 0.03 0.01"/>
    <camera name="overview" pos="1.22 0.00 0.92" xyaxes="0 1 0 -0.46 0 0.88"/>

    <body name="gripper_mocap" mocap="true" pos="0.36 -0.33 0.30" quat="0.707107 0 -0.707107 0"/>
    <body name="scoop_mocap" mocap="true" pos="0.42 0.28 0.20" quat="1 0 0 0"/>

    <body name="gripper_ctrl_base" pos="0.36 -0.33 0.30">
      <joint name="gripper_ctrl_x" type="slide" axis="1 0 0" limited="true" range="0.20 1.00"/>
      <body name="gripper_ctrl_y_body">
        <joint name="gripper_ctrl_y" type="slide" axis="0 1 0" limited="true" range="-0.60 0.60"/>
        <body name="gripper_ctrl_z_body">
          <joint name="gripper_ctrl_z" type="slide" axis="0 0 1" limited="true" range="0.04 0.70"/>
          <body name="gripper_ctrl_yaw_body">
            <joint name="gripper_ctrl_yaw" type="hinge" axis="0 0 1" limited="true" range="-3.1416 3.1416"/>
            <body name="gripper_ctrl_pitch_body">
              <joint name="gripper_ctrl_pitch" type="hinge" axis="0 1 0" limited="true" range="-3.1416 3.1416"/>
              <body name="gripper_ctrl_roll_body">
                <joint name="gripper_ctrl_roll" type="hinge" axis="1 0 0" limited="true" range="-3.1416 3.1416"/>
              </body>
            </body>
          </body>
        </body>
      </body>
    </body>

    <body name="scoop_ctrl_base" pos="0.42 0.28 0.20">
      <joint name="scoop_ctrl_x" type="slide" axis="1 0 0" limited="true" range="0.20 1.00"/>
      <body name="scoop_ctrl_y_body">
        <joint name="scoop_ctrl_y" type="slide" axis="0 1 0" limited="true" range="-0.60 0.60"/>
        <body name="scoop_ctrl_z_body">
          <joint name="scoop_ctrl_z" type="slide" axis="0 0 1" limited="true" range="0.04 0.70"/>
          <body name="scoop_ctrl_yaw_body">
            <joint name="scoop_ctrl_yaw" type="hinge" axis="0 0 1" limited="true" range="-3.1416 3.1416"/>
            <body name="scoop_ctrl_pitch_body">
              <joint name="scoop_ctrl_pitch" type="hinge" axis="0 1 0" limited="true" range="-3.1416 3.1416"/>
              <body name="scoop_ctrl_roll_body">
                <joint name="scoop_ctrl_roll" type="hinge" axis="1 0 0" limited="true" range="-3.1416 3.1416"/>
              </body>
            </body>
          </body>
        </body>
      </body>
    </body>

    <body name="gripper_tool" pos="0.36 -0.33 0.30" quat="0.707107 0 -0.707107 0">
      <freejoint name="gripper_tool_free"/>
      <inertial pos="0 0 0.04" mass="0.08" diaginertia="0.0002 0.0002 0.0002"/>
      <geom name="gripper_palm" type="box" pos="0 0 0.030" size="0.020 0.026 0.030" rgba="0.14 0.14 0.14 1"/>
      <body name="left_finger_body" pos="0 0 0.072">
        <joint name="left_finger_slide" type="slide" axis="0 1 0" limited="true" range="0.010 0.040" damping="12"/>
        <geom name="left_finger_geom" type="box" pos="0 0.020 0" size="0.012 0.006 0.040" rgba="0.10 0.10 0.10 1" friction="2.2 0.05 0.01"/>
      </body>
      <body name="right_finger_body" pos="0 0 0.072">
        <joint name="right_finger_slide" type="slide" axis="0 -1 0" limited="true" range="0.010 0.040" damping="12"/>
        <geom name="right_finger_geom" type="box" pos="0 -0.020 0" size="0.012 0.006 0.040" rgba="0.10 0.10 0.10 1" friction="2.2 0.05 0.01"/>
      </body>
      <site name="gripper_pinch_site" pos="0 0 0.074" size="0.006" rgba="1 0 0 1"/>
    </body>

    <body name="scoop_tool" pos="0.42 0.28 0.20" quat="1 0 0 0">
      <freejoint name="scoop_tool_free"/>
      <inertial pos="0 0 0.02" mass="0.10" diaginertia="0.0003 0.0003 0.0003"/>
      <geom name="scoop_plate" type="box" pos="0.062 0 0" size="0.062 0.085 0.004" rgba="0.28 0.31 0.35 1" friction="1.7 0.05 0.01"/>
      <geom name="scoop_lip" type="box" pos="0.126 0 0.014" size="0.004 0.085 0.014" rgba="0.24 0.27 0.30 1" friction="1.7 0.05 0.01"/>
      <geom name="scoop_left_rail" type="box" pos="0.062 0.082 0.018" size="0.056 0.004 0.018" rgba="0.24 0.27 0.30 1"/>
      <geom name="scoop_right_rail" type="box" pos="0.062 -0.082 0.018" size="0.056 0.004 0.018" rgba="0.24 0.27 0.30 1"/>
      <geom name="scoop_backstop" type="box" pos="0.000 0 0.022" size="0.006 0.082 0.022" rgba="0.24 0.27 0.30 1"/>
      <site name="scoop_tip_site" pos="0.126 0 0.005" size="0.005" rgba="0 0 1 1"/>
      <site name="scoop_center_site" pos="0.060 0 0.020" size="0.005" rgba="0 0.7 1 1"/>
      <site name="score_overlay_site" pos="0.030 0 0.080" size="0.008" rgba="0 1 0 0.8"/>
    </body>


    <body name="sack_0" pos="0.4581 0.0612 0.1272" euler="0.1105 -0.0086 2.6535">
      <freejoint name="sack_0_free"/>

      <geom name="sack_0_visual" type="mesh" mesh="sack_0_visual_mesh" rgba="0.840 0.740 0.480 0.92" contype="0" conaffinity="0"/>
      <site name="sack_0_center_site" pos="0 0 0.000" size="0.006" rgba="0 1 0 1"/>
      <site name="sack_0_top_site" pos="0 -0.0060 0.1498" size="0.007" rgba="1 0.5 0 1"/>
      <site name="sack_0_side_site" pos="0.0000 -0.0481 0.018" size="0.007" rgba="1 0.8 0 1"/>

      <geom name="sack_0_core_geom" type="ellipsoid" pos="0 0 0.0059" size="0.0498 0.0413 0.0880" mass="1.0288" rgba="0.840 0.740 0.480 0.12" friction="1.0 0.03 0.01"/>
      <geom name="sack_0_core_front" type="capsule" fromto="-0.0200 0 -0.0200 0.0450 0 0.0600" size="0.0306" mass="0.2450" rgba="0.840 0.740 0.480 0.10"/>
      <geom name="sack_0_core_left" type="capsule" fromto="-0.008 0.0290 -0.010 0.018 0.0470 0.060" size="0.0241" mass="0.4409" rgba="0.840 0.740 0.480 0.10"/>
      <geom name="sack_0_core_right" type="capsule" fromto="-0.006 -0.0290 -0.008 0.020 -0.0490 0.054" size="0.0221" mass="0.4409" rgba="0.840 0.740 0.480 0.10"/>

      <body name="sack_0_bottom_skin" pos="0 -0.0029 -0.0939">
        <joint name="sack_0_bottom_x" type="slide" axis="1 0 0" limited="true" range="-0.012 0.012" damping="18" stiffness="476.5"/>
        <joint name="sack_0_bottom_y" type="slide" axis="0 1 0" limited="true" range="-0.012 0.012" damping="18" stiffness="476.5"/>
        <joint name="sack_0_bottom_z" type="slide" axis="0 0 1" limited="true" range="-0.008 0.020" damping="24" stiffness="586.9"/>
        <geom name="sack_0_bottom_support" type="box" size="0.0714 0.0541 0.0100" mass="0.1960" rgba="0.840 0.740 0.480 0.34" friction="1.55 0.05 0.01"/>
      </body>

      <body name="sack_0_top_skin" pos="0.0000 -0.0060 0.1198">
        <joint name="sack_0_top_x" type="slide" axis="1 0 0" limited="true" range="-0.018 0.018" damping="12" stiffness="183.1"/>
        <joint name="sack_0_top_y" type="slide" axis="0 1 0" limited="true" range="-0.018 0.018" damping="12" stiffness="183.1"/>
        <joint name="sack_0_top_z" type="slide" axis="0 0 1" limited="true" range="-0.040 0.010" damping="14" stiffness="135.5"/>
        <geom name="sack_0_top_grip" type="box" size="0.0554 0.0381 0.0150" mass="0.1470" rgba="0.840 0.740 0.480 0.26" friction="2.2 0.05 0.01"/>
      </body>

      <body name="sack_0_left_skin" pos="0 0.0671 0.010">
        <joint name="sack_0_left_side_slide" type="slide" axis="0 -1 0" limited="true" range="-0.028 0.016" damping="16" stiffness="240.8"/>
        <geom name="sack_0_side_left" type="box" size="0.0674 0.0090 0.0919" mass="0.1470" rgba="0.840 0.740 0.480 0.24"/>
      </body>

      <body name="sack_0_right_skin" pos="0 -0.0631 0.010">
        <joint name="sack_0_right_side_slide" type="slide" axis="0 1 0" limited="true" range="-0.028 0.016" damping="16" stiffness="223.2"/>
        <geom name="sack_0_side_right" type="box" size="0.0674 0.0090 0.0919" mass="0.1470" rgba="0.840 0.740 0.480 0.24"/>
      </body>

      <body name="sack_0_front_skin" pos="0.0614 0 0.000">
        <joint name="sack_0_front_slide" type="slide" axis="-1 0 0" limited="true" range="-0.022 0.012" damping="15" stiffness="228.3"/>
        <geom name="sack_0_front_panel" type="box" size="0.0090 0.0541 0.0899" mass="0.1225" rgba="0.840 0.740 0.480 0.22"/>
      </body>

      <body name="sack_0_back_skin" pos="-0.0614 0 0.000">
        <joint name="sack_0_back_slide" type="slide" axis="1 0 0" limited="true" range="-0.022 0.012" damping="15" stiffness="210.7"/>
        <geom name="sack_0_back_panel" type="box" size="0.0090 0.0541 0.0899" mass="0.1225" rgba="0.840 0.740 0.480 0.22"/>
      </body>

      <body name="sack_0_local_patch" pos="0.0000 -0.0210 0.0345">
        <joint name="sack_0_bulge_y" type="slide" axis="0 1 0" limited="true" range="-0.020 0.020" damping="8" stiffness="89.0"/>
        <joint name="sack_0_bulge_z" type="slide" axis="0 0 1" limited="true" range="-0.014 0.028" damping="8" stiffness="91.7"/>
        <geom name="sack_0_compliant_patch" type="ellipsoid" size="0.0201 0.0162 0.0261" mass="0.0980" rgba="0.840 0.740 0.480 0.28"/>
      </body>
    </body>

    <body name="sack_1" pos="0.5778 0.0464 0.1279" euler="-0.2233 -0.0335 -2.6896">
      <freejoint name="sack_1_free"/>

      <geom name="sack_1_visual" type="mesh" mesh="sack_1_visual_mesh" rgba="0.820 0.670 0.440 0.92" contype="0" conaffinity="0"/>
      <site name="sack_1_center_site" pos="0 0 0.000" size="0.006" rgba="0 1 0 1"/>
      <site name="sack_1_top_site" pos="0 -0.0060 0.0867" size="0.007" rgba="1 0.5 0 1"/>
      <site name="sack_1_side_site" pos="0.0000 -0.0500 0.018" size="0.007" rgba="1 0.8 0 1"/>

      <geom name="sack_1_core_geom" type="ellipsoid" pos="0 0 0.0055" size="0.0458 0.0360 0.0684" mass="0.7239" rgba="0.820 0.670 0.440 0.12" friction="1.0 0.03 0.01"/>
      <geom name="sack_1_core_front" type="capsule" fromto="-0.0200 0 -0.0200 0.0450 0 0.0600" size="0.0305" mass="0.1724" rgba="0.820 0.670 0.440 0.10"/>
      <geom name="sack_1_core_left" type="capsule" fromto="-0.008 0.0221 -0.010 0.018 0.0401 0.060" size="0.0240" mass="0.3102" rgba="0.820 0.670 0.440 0.10"/>
      <geom name="sack_1_core_right" type="capsule" fromto="-0.006 -0.0221 -0.008 0.020 -0.0421 0.054" size="0.0220" mass="0.3102" rgba="0.820 0.670 0.440 0.10"/>

      <body name="sack_1_bottom_skin" pos="0 -0.0094 -0.0839">
        <joint name="sack_1_bottom_x" type="slide" axis="1 0 0" limited="true" range="-0.012 0.012" damping="18" stiffness="474.8"/>
        <joint name="sack_1_bottom_y" type="slide" axis="0 1 0" limited="true" range="-0.012 0.012" damping="18" stiffness="474.8"/>
        <joint name="sack_1_bottom_z" type="slide" axis="0 0 1" limited="true" range="-0.008 0.020" damping="24" stiffness="584.7"/>
        <geom name="sack_1_bottom_support" type="box" size="0.0734 0.0560 0.0100" mass="0.1379" rgba="0.820 0.670 0.440 0.34" friction="1.55 0.05 0.01"/>
      </body>

      <body name="sack_1_top_skin" pos="0.0000 -0.0060 0.0567">
        <joint name="sack_1_top_x" type="slide" axis="1 0 0" limited="true" range="-0.018 0.018" damping="12" stiffness="182.4"/>
        <joint name="sack_1_top_y" type="slide" axis="0 1 0" limited="true" range="-0.018 0.018" damping="12" stiffness="182.4"/>
        <joint name="sack_1_top_z" type="slide" axis="0 0 1" limited="true" range="-0.040 0.010" damping="14" stiffness="134.9"/>
        <geom name="sack_1_top_grip" type="box" size="0.0574 0.0400 0.0150" mass="0.1034" rgba="0.820 0.670 0.440 0.26" friction="2.2 0.05 0.01"/>
      </body>

      <body name="sack_1_left_skin" pos="0 0.0620 0.010">
        <joint name="sack_1_left_side_slide" type="slide" axis="0 -1 0" limited="true" range="-0.028 0.016" damping="16" stiffness="238.3"/>
        <geom name="sack_1_side_left" type="box" size="0.0694 0.0090 0.0819" mass="0.1034" rgba="0.820 0.670 0.440 0.24"/>
      </body>

      <body name="sack_1_right_skin" pos="0 -0.0580 0.010">
        <joint name="sack_1_right_side_slide" type="slide" axis="0 1 0" limited="true" range="-0.028 0.016" damping="16" stiffness="220.8"/>
        <geom name="sack_1_side_right" type="box" size="0.0694 0.0090 0.0819" mass="0.1034" rgba="0.820 0.670 0.440 0.24"/>
      </body>

      <body name="sack_1_front_skin" pos="0.0634 0 0.000">
        <joint name="sack_1_front_slide" type="slide" axis="-1 0 0" limited="true" range="-0.022 0.012" damping="15" stiffness="227.4"/>
        <geom name="sack_1_front_panel" type="box" size="0.0090 0.0560 0.0799" mass="0.0862" rgba="0.820 0.670 0.440 0.22"/>
      </body>

      <body name="sack_1_back_skin" pos="-0.0634 0 0.000">
        <joint name="sack_1_back_slide" type="slide" axis="1 0 0" limited="true" range="-0.022 0.012" damping="15" stiffness="209.9"/>
        <geom name="sack_1_back_panel" type="box" size="0.0090 0.0560 0.0799" mass="0.0862" rgba="0.820 0.670 0.440 0.22"/>
      </body>

      <body name="sack_1_local_patch" pos="0.0000 -0.0141 0.0351">
        <joint name="sack_1_bulge_y" type="slide" axis="0 1 0" limited="true" range="-0.020 0.020" damping="8" stiffness="90.1"/>
        <joint name="sack_1_bulge_z" type="slide" axis="0 0 1" limited="true" range="-0.014 0.028" damping="8" stiffness="92.6"/>
        <geom name="sack_1_compliant_patch" type="ellipsoid" size="0.0200 0.0160 0.0264" mass="0.0689" rgba="0.820 0.670 0.440 0.28"/>
      </body>
    </body>

    <body name="sack_2" pos="0.6926 0.1857 0.1318" euler="-0.2315 -0.2183 -1.2642">
      <freejoint name="sack_2_free"/>

      <geom name="sack_2_visual" type="mesh" mesh="sack_2_visual_mesh" rgba="0.760 0.600 0.400 0.92" contype="0" conaffinity="0"/>
      <site name="sack_2_center_site" pos="0 0 0.000" size="0.006" rgba="0 1 0 1"/>
      <site name="sack_2_top_site" pos="0 -0.0060 0.1277" size="0.007" rgba="1 0.5 0 1"/>
      <site name="sack_2_side_site" pos="0.0000 -0.0548 0.018" size="0.007" rgba="1 0.8 0 1"/>

      <geom name="sack_2_core_geom" type="ellipsoid" pos="0 0 0.0059" size="0.0441 0.0340 0.0769" mass="0.8605" rgba="0.760 0.600 0.400 0.12" friction="1.0 0.03 0.01"/>
      <geom name="sack_2_core_front" type="capsule" fromto="-0.0200 0 -0.0200 0.0450 0 0.0600" size="0.0296" mass="0.2049" rgba="0.760 0.600 0.400 0.10"/>
      <geom name="sack_2_core_left" type="capsule" fromto="-0.008 0.0382 -0.010 0.018 0.0562 0.060" size="0.0242" mass="0.3688" rgba="0.760 0.600 0.400 0.10"/>
      <geom name="sack_2_core_right" type="capsule" fromto="-0.006 -0.0382 -0.008 0.020 -0.0582 0.054" size="0.0222" mass="0.3688" rgba="0.760 0.600 0.400 0.10"/>

      <body name="sack_2_bottom_skin" pos="0 0.0063 -0.0968">
        <joint name="sack_2_bottom_x" type="slide" axis="1 0 0" limited="true" range="-0.012 0.012" damping="18" stiffness="448.2"/>
        <joint name="sack_2_bottom_y" type="slide" axis="0 1 0" limited="true" range="-0.012 0.012" damping="18" stiffness="448.2"/>
        <joint name="sack_2_bottom_z" type="slide" axis="0 0 1" limited="true" range="-0.008 0.020" damping="24" stiffness="552.2"/>
        <geom name="sack_2_bottom_support" type="box" size="0.0746 0.0608 0.0100" mass="0.1639" rgba="0.760 0.600 0.400 0.34" friction="1.55 0.05 0.01"/>
      </body>

      <body name="sack_2_top_skin" pos="0.0000 -0.0060 0.0977">
        <joint name="sack_2_top_x" type="slide" axis="1 0 0" limited="true" range="-0.018 0.018" damping="12" stiffness="172.1"/>
        <joint name="sack_2_top_y" type="slide" axis="0 1 0" limited="true" range="-0.018 0.018" damping="12" stiffness="172.1"/>
        <joint name="sack_2_top_z" type="slide" axis="0 0 1" limited="true" range="-0.040 0.010" damping="14" stiffness="126.1"/>
        <geom name="sack_2_top_grip" type="box" size="0.0586 0.0448 0.0150" mass="0.1229" rgba="0.760 0.600 0.400 0.26" friction="2.2 0.05 0.01"/>
      </body>

      <body name="sack_2_left_skin" pos="0 0.0830 0.010">
        <joint name="sack_2_left_side_slide" type="slide" axis="0 -1 0" limited="true" range="-0.028 0.016" damping="16" stiffness="221.8"/>
        <geom name="sack_2_side_left" type="box" size="0.0706 0.0090 0.0948" mass="0.1229" rgba="0.760 0.600 0.400 0.24"/>
      </body>

      <body name="sack_2_right_skin" pos="0 -0.0790 0.010">
        <joint name="sack_2_right_side_slide" type="slide" axis="0 1 0" limited="true" range="-0.028 0.016" damping="16" stiffness="205.8"/>
        <geom name="sack_2_side_right" type="box" size="0.0706 0.0090 0.0948" mass="0.1229" rgba="0.760 0.600 0.400 0.24"/>
      </body>

      <body name="sack_2_front_skin" pos="0.0646 0 0.000">
        <joint name="sack_2_front_slide" type="slide" axis="-1 0 0" limited="true" range="-0.022 0.012" damping="15" stiffness="214.1"/>
        <geom name="sack_2_front_panel" type="box" size="0.0090 0.0608 0.0928" mass="0.1024" rgba="0.760 0.600 0.400 0.22"/>
      </body>

      <body name="sack_2_back_skin" pos="-0.0646 0 0.000">
        <joint name="sack_2_back_slide" type="slide" axis="1 0 0" limited="true" range="-0.022 0.012" damping="15" stiffness="198.1"/>
        <geom name="sack_2_back_panel" type="box" size="0.0090 0.0608 0.0928" mass="0.1024" rgba="0.760 0.600 0.400 0.22"/>
      </body>

      <body name="sack_2_local_patch" pos="0.0000 -0.0302 0.0439">
        <joint name="sack_2_bulge_y" type="slide" axis="0 1 0" limited="true" range="-0.020 0.020" damping="8" stiffness="107.9"/>
        <joint name="sack_2_bulge_z" type="slide" axis="0 0 1" limited="true" range="-0.014 0.028" damping="8" stiffness="105.9"/>
        <geom name="sack_2_compliant_patch" type="ellipsoid" size="0.0202 0.0164 0.0261" mass="0.0819" rgba="0.760 0.600 0.400 0.28"/>
      </body>
    </body>

    <body name="sack_3" pos="0.7346 -0.1280 0.1053" euler="-0.0904 0.1356 -2.8480">
      <freejoint name="sack_3_free"/>

      <geom name="sack_3_visual" type="mesh" mesh="sack_3_visual_mesh" rgba="0.840 0.740 0.480 0.92" contype="0" conaffinity="0"/>
      <site name="sack_3_center_site" pos="0 0 0.000" size="0.006" rgba="0 1 0 1"/>
      <site name="sack_3_top_site" pos="0 0.0060 0.1434" size="0.007" rgba="1 0.5 0 1"/>
      <site name="sack_3_side_site" pos="0.0000 0.0522 0.018" size="0.007" rgba="1 0.8 0 1"/>

      <geom name="sack_3_core_geom" type="ellipsoid" pos="0 0 0.0059" size="0.0512 0.0435 0.0917" mass="1.0826" rgba="0.840 0.740 0.480 0.12" friction="1.0 0.03 0.01"/>
      <geom name="sack_3_core_front" type="capsule" fromto="-0.0200 0 -0.0200 0.0450 0 0.0600" size="0.0322" mass="0.2578" rgba="0.840 0.740 0.480 0.10"/>
      <geom name="sack_3_core_left" type="capsule" fromto="-0.008 0.0293 -0.010 0.018 0.0473 0.060" size="0.0241" mass="0.4640" rgba="0.840 0.740 0.480 0.10"/>
      <geom name="sack_3_core_right" type="capsule" fromto="-0.006 -0.0293 -0.008 0.020 -0.0493 0.054" size="0.0221" mass="0.4640" rgba="0.840 0.740 0.480 0.10"/>

      <body name="sack_3_bottom_skin" pos="0 0.0090 -0.0898">
        <joint name="sack_3_bottom_x" type="slide" axis="1 0 0" limited="true" range="-0.012 0.012" damping="18" stiffness="527.3"/>
        <joint name="sack_3_bottom_y" type="slide" axis="0 1 0" limited="true" range="-0.012 0.012" damping="18" stiffness="527.3"/>
        <joint name="sack_3_bottom_z" type="slide" axis="0 0 1" limited="true" range="-0.008 0.020" damping="24" stiffness="648.9"/>
        <geom name="sack_3_bottom_support" type="box" size="0.0730 0.0582 0.0100" mass="0.2062" rgba="0.840 0.740 0.480 0.34" friction="1.55 0.05 0.01"/>
      </body>

      <body name="sack_3_top_skin" pos="0.0000 0.0060 0.1134">
        <joint name="sack_3_top_x" type="slide" axis="1 0 0" limited="true" range="-0.018 0.018" damping="12" stiffness="202.8"/>
        <joint name="sack_3_top_y" type="slide" axis="0 1 0" limited="true" range="-0.018 0.018" damping="12" stiffness="202.8"/>
        <joint name="sack_3_top_z" type="slide" axis="0 0 1" limited="true" range="-0.040 0.010" damping="14" stiffness="152.4"/>
        <geom name="sack_3_top_grip" type="box" size="0.0570 0.0422 0.0150" mass="0.1547" rgba="0.840 0.740 0.480 0.26" friction="2.2 0.05 0.01"/>
      </body>

      <body name="sack_3_left_skin" pos="0 0.0715 0.010">
        <joint name="sack_3_left_side_slide" type="slide" axis="0 -1 0" limited="true" range="-0.028 0.016" damping="16" stiffness="274.6"/>
        <geom name="sack_3_side_left" type="box" size="0.0690 0.0090 0.0878" mass="0.1547" rgba="0.840 0.740 0.480 0.24"/>
      </body>

      <body name="sack_3_right_skin" pos="0 -0.0675 0.010">
        <joint name="sack_3_right_side_slide" type="slide" axis="0 1 0" limited="true" range="-0.028 0.016" damping="16" stiffness="254.2"/>
        <geom name="sack_3_side_right" type="box" size="0.0690 0.0090 0.0878" mass="0.1547" rgba="0.840 0.740 0.480 0.24"/>
      </body>

      <body name="sack_3_front_skin" pos="0.0630 0 0.000">
        <joint name="sack_3_front_slide" type="slide" axis="-1 0 0" limited="true" range="-0.022 0.012" damping="15" stiffness="253.6"/>
        <geom name="sack_3_front_panel" type="box" size="0.0090 0.0582 0.0858" mass="0.1289" rgba="0.840 0.740 0.480 0.22"/>
      </body>

      <body name="sack_3_back_skin" pos="-0.0630 0 0.000">
        <joint name="sack_3_back_slide" type="slide" axis="1 0 0" limited="true" range="-0.022 0.012" damping="15" stiffness="233.2"/>
        <geom name="sack_3_back_panel" type="box" size="0.0090 0.0582 0.0858" mass="0.1289" rgba="0.840 0.740 0.480 0.22"/>
      </body>

      <body name="sack_3_local_patch" pos="0.0000 0.0213 0.0176">
        <joint name="sack_3_bulge_y" type="slide" axis="0 1 0" limited="true" range="-0.020 0.020" damping="8" stiffness="60.0"/>
        <joint name="sack_3_bulge_z" type="slide" axis="0 0 1" limited="true" range="-0.014 0.028" damping="8" stiffness="70.0"/>
        <geom name="sack_3_compliant_patch" type="ellipsoid" size="0.0201 0.0162 0.0261" mass="0.1031" rgba="0.840 0.740 0.480 0.28"/>
      </body>
    </body>

    <body name="sack_4" pos="0.6901 0.0586 0.1152" euler="-0.1059 -0.1084 2.6653">
      <freejoint name="sack_4_free"/>

      <geom name="sack_4_visual" type="mesh" mesh="sack_4_visual_mesh" rgba="0.820 0.670 0.440 0.92" contype="0" conaffinity="0"/>
      <site name="sack_4_center_site" pos="0 0 0.000" size="0.006" rgba="0 1 0 1"/>
      <site name="sack_4_top_site" pos="0 -0.0060 0.1262" size="0.007" rgba="1 0.5 0 1"/>
      <site name="sack_4_side_site" pos="0.0000 -0.0489 0.018" size="0.007" rgba="1 0.8 0 1"/>

      <geom name="sack_4_core_geom" type="ellipsoid" pos="0 0 0.0057" size="0.0454 0.0355 0.0677" mass="0.7394" rgba="0.820 0.670 0.440 0.12" friction="1.0 0.03 0.01"/>
      <geom name="sack_4_core_front" type="capsule" fromto="-0.0200 0 -0.0200 0.0450 0 0.0600" size="0.0300" mass="0.1760" rgba="0.820 0.670 0.440 0.10"/>
      <geom name="sack_4_core_left" type="capsule" fromto="-0.008 0.0228 -0.010 0.018 0.0408 0.060" size="0.0240" mass="0.3169" rgba="0.820 0.670 0.440 0.10"/>
      <geom name="sack_4_core_right" type="capsule" fromto="-0.006 -0.0228 -0.008 0.020 -0.0428 0.054" size="0.0220" mass="0.3169" rgba="0.820 0.670 0.440 0.10"/>

      <body name="sack_4_bottom_skin" pos="0 -0.0150 -0.1113">
        <joint name="sack_4_bottom_x" type="slide" axis="1 0 0" limited="true" range="-0.012 0.012" damping="18" stiffness="461.1"/>
        <joint name="sack_4_bottom_y" type="slide" axis="0 1 0" limited="true" range="-0.012 0.012" damping="18" stiffness="461.1"/>
        <joint name="sack_4_bottom_z" type="slide" axis="0 0 1" limited="true" range="-0.008 0.020" damping="24" stiffness="568.1"/>
        <geom name="sack_4_bottom_support" type="box" size="0.0730 0.0549 0.0100" mass="0.1408" rgba="0.820 0.670 0.440 0.34" friction="1.55 0.05 0.01"/>
      </body>

      <body name="sack_4_top_skin" pos="0.0000 -0.0060 0.0962">
        <joint name="sack_4_top_x" type="slide" axis="1 0 0" limited="true" range="-0.018 0.018" damping="12" stiffness="177.1"/>
        <joint name="sack_4_top_y" type="slide" axis="0 1 0" limited="true" range="-0.018 0.018" damping="12" stiffness="177.1"/>
        <joint name="sack_4_top_z" type="slide" axis="0 0 1" limited="true" range="-0.040 0.010" damping="14" stiffness="130.4"/>
        <geom name="sack_4_top_grip" type="box" size="0.0570 0.0389 0.0150" mass="0.1056" rgba="0.820 0.670 0.440 0.26" friction="2.2 0.05 0.01"/>
      </body>

      <body name="sack_4_left_skin" pos="0 0.0616 0.010">
        <joint name="sack_4_left_side_slide" type="slide" axis="0 -1 0" limited="true" range="-0.028 0.016" damping="16" stiffness="229.9"/>
        <geom name="sack_4_side_left" type="box" size="0.0690 0.0090 0.1093" mass="0.1056" rgba="0.820 0.670 0.440 0.24"/>
      </body>

      <body name="sack_4_right_skin" pos="0 -0.0576 0.010">
        <joint name="sack_4_right_side_slide" type="slide" axis="0 1 0" limited="true" range="-0.028 0.016" damping="16" stiffness="213.2"/>
        <geom name="sack_4_side_right" type="box" size="0.0690 0.0090 0.1093" mass="0.1056" rgba="0.820 0.670 0.440 0.24"/>
      </body>

      <body name="sack_4_front_skin" pos="0.0630 0 0.000">
        <joint name="sack_4_front_slide" type="slide" axis="-1 0 0" limited="true" range="-0.022 0.012" damping="15" stiffness="220.6"/>
        <geom name="sack_4_front_panel" type="box" size="0.0090 0.0549 0.1073" mass="0.0880" rgba="0.820 0.670 0.440 0.22"/>
      </body>

      <body name="sack_4_back_skin" pos="-0.0630 0 0.000">
        <joint name="sack_4_back_slide" type="slide" axis="1 0 0" limited="true" range="-0.022 0.012" damping="15" stiffness="203.8"/>
        <geom name="sack_4_back_panel" type="box" size="0.0090 0.0549 0.1073" mass="0.0880" rgba="0.820 0.670 0.440 0.22"/>
      </body>

      <body name="sack_4_local_patch" pos="0.0000 -0.0148 0.0396">
        <joint name="sack_4_bulge_y" type="slide" axis="0 1 0" limited="true" range="-0.020 0.020" damping="8" stiffness="99.2"/>
        <joint name="sack_4_bulge_z" type="slide" axis="0 0 1" limited="true" range="-0.014 0.028" damping="8" stiffness="99.4"/>
        <geom name="sack_4_compliant_patch" type="ellipsoid" size="0.0200 0.0161 0.0262" mass="0.0704" rgba="0.820 0.670 0.440 0.28"/>
      </body>
    </body>
  </worldbody>

  <equality>
    <weld name="gripper_follow" body1="gripper_mocap" body2="gripper_tool" torquescale="400" solref="0.002 1" solimp="0.99 0.999 0.0001"/>
    <weld name="scoop_follow" body1="scoop_mocap" body2="scoop_tool" torquescale="500" solref="0.002 1" solimp="0.99 0.999 0.0001"/>
  </equality>

  <actuator>
    <position name="gripper_ctrl_x_act" joint="gripper_ctrl_x" ctrlrange="0.20 1.00" kp="3500" forcerange="-300 300"/>
    <position name="gripper_ctrl_y_act" joint="gripper_ctrl_y" ctrlrange="-0.60 0.60" kp="3500" forcerange="-300 300"/>
    <position name="gripper_ctrl_z_act" joint="gripper_ctrl_z" ctrlrange="0.04 0.70" kp="3500" forcerange="-300 300"/>
    <position name="gripper_ctrl_yaw_act" joint="gripper_ctrl_yaw" ctrlrange="-3.1416 3.1416" kp="1800" forcerange="-250 250"/>
    <position name="gripper_ctrl_pitch_act" joint="gripper_ctrl_pitch" ctrlrange="-3.1416 3.1416" kp="1800" forcerange="-250 250"/>
    <position name="gripper_ctrl_roll_act" joint="gripper_ctrl_roll" ctrlrange="-3.1416 3.1416" kp="1800" forcerange="-250 250"/>
    <position name="scoop_ctrl_x_act" joint="scoop_ctrl_x" ctrlrange="0.20 1.00" kp="3500" forcerange="-300 300"/>
    <position name="scoop_ctrl_y_act" joint="scoop_ctrl_y" ctrlrange="-0.60 0.60" kp="3500" forcerange="-300 300"/>
    <position name="scoop_ctrl_z_act" joint="scoop_ctrl_z" ctrlrange="0.04 0.70" kp="3500" forcerange="-300 300"/>
    <position name="scoop_ctrl_yaw_act" joint="scoop_ctrl_yaw" ctrlrange="-3.1416 3.1416" kp="1800" forcerange="-250 250"/>
    <position name="scoop_ctrl_pitch_act" joint="scoop_ctrl_pitch" ctrlrange="-3.1416 3.1416" kp="1800" forcerange="-250 250"/>
    <position name="scoop_ctrl_roll_act" joint="scoop_ctrl_roll" ctrlrange="-3.1416 3.1416" kp="1800" forcerange="-250 250"/>
    <position name="left_finger_act" joint="left_finger_slide" ctrlrange="0.010 0.040" kp="2800" forcerange="-220 220"/>
    <position name="right_finger_act" joint="right_finger_slide" ctrlrange="0.010 0.040" kp="2800" forcerange="-220 220"/>
  </actuator>

  <contact>
    <exclude body1="sack_0_top_skin" body2="sack_0_left_skin"/>
    <exclude body1="sack_0_top_skin" body2="sack_0_right_skin"/>
    <exclude body1="sack_1_top_skin" body2="sack_1_left_skin"/>
    <exclude body1="sack_1_top_skin" body2="sack_1_right_skin"/>
    <exclude body1="sack_2_top_skin" body2="sack_2_left_skin"/>
    <exclude body1="sack_2_top_skin" body2="sack_2_right_skin"/>
    <exclude body1="sack_3_top_skin" body2="sack_3_left_skin"/>
    <exclude body1="sack_3_top_skin" body2="sack_3_right_skin"/>
    <exclude body1="sack_4_top_skin" body2="sack_4_left_skin"/>
    <exclude body1="sack_4_top_skin" body2="sack_4_right_skin"/>
  </contact>
</mujoco>
