<mujoco model="deformable_preview_deformable_pile">
  <compiler angle="radian" coordinate="local"/>
  <option gravity="0 0 -9.81" timestep="0.002" iterations="120" tolerance="1e-10"/>
  <size memory="1024M" nconmax="20000"/>

  <visual>
    <global azimuth="130" elevation="-22"/>
    <headlight ambient="0.35 0.35 0.35" diffuse="0.80 0.80 0.80" specular="0.15 0.15 0.15"/>
  </visual>

  <worldbody>
    <light name="key" pos="0.9 0.0 1.8" dir="-0.2 0 -1" directional="true"/>
    <geom name="floor" type="plane" size="2 2 0.1" rgba="0.93 0.93 0.93 1"/>
    <geom name="work_pad" type="box" pos="0.62 0 0.010" size="0.32 0.32 0.010" rgba="0.60 0.61 0.62 1" friction="1.5 0.05 0.01"/>
    <camera name="overview" pos="1.26 0.00 0.96" xyaxes="0 1 0 -0.48 0 0.88"/>

    <body name="dsack_0" pos="0.7749 -0.0844 0.1855" euler="-0.1426 0.4257 -1.2358">
      <freejoint name="dsack_0_free"/>
      <inertial pos="0 0 0" mass="0.02" diaginertia="0.0002 0.0002 0.0002"/>
      <flexcomp name="dsack_0_flex" type="mesh" file="../../object/sack8.obj" dim="2" mass="0.9175" radius="0.00442">
        <edge damping="0.18"/>
        <contact condim="4" friction="1.4 0.05 0.01" solref="0.004 1" solimp="0.95 0.99 0.002"/>
      </flexcomp>
      
      <body name="dsack_0_payload0" pos="0.000 0.000 0.010">
        <joint name="dsack_0_payload0_x" type="slide" axis="1 0 0" limited="true" range="-0.020 0.020" damping="4"/>
        <joint name="dsack_0_payload0_y" type="slide" axis="0 1 0" limited="true" range="-0.020 0.020" damping="4"/>
        <joint name="dsack_0_payload0_z" type="slide" axis="0 0 1" limited="true" range="-0.030 0.030" damping="4"/>
        <geom type="sphere" size="0.018" mass="0.1468" rgba="0.840 0.740 0.500 0.10" friction="0.9 0.03 0.01"/>
      </body>
      <body name="dsack_0_payload1" pos="0.022 0.000 -0.012">
        <joint name="dsack_0_payload1_x" type="slide" axis="1 0 0" limited="true" range="-0.020 0.020" damping="4"/>
        <joint name="dsack_0_payload1_y" type="slide" axis="0 1 0" limited="true" range="-0.020 0.020" damping="4"/>
        <joint name="dsack_0_payload1_z" type="slide" axis="0 0 1" limited="true" range="-0.030 0.030" damping="4"/>
        <geom type="sphere" size="0.016" mass="0.1284" rgba="0.840 0.740 0.500 0.10" friction="0.9 0.03 0.01"/>
      </body>
      <body name="dsack_0_payload2" pos="-0.020 0.010 0.000">
        <joint name="dsack_0_payload2_x" type="slide" axis="1 0 0" limited="true" range="-0.020 0.020" damping="4"/>
        <joint name="dsack_0_payload2_y" type="slide" axis="0 1 0" limited="true" range="-0.020 0.020" damping="4"/>
        <joint name="dsack_0_payload2_z" type="slide" axis="0 0 1" limited="true" range="-0.030 0.030" damping="4"/>
        <geom type="sphere" size="0.015" mass="0.1101" rgba="0.840 0.740 0.500 0.10" friction="0.9 0.03 0.01"/>
      </body>
      <site name="dsack_0_site" pos="0 0 0" size="0.006" rgba="0.840 0.740 0.500 1"/>
    </body>

    <body name="dsack_1" pos="0.5784 -0.0501 0.1757" euler="0.7309 0.0488 1.2891">
      <freejoint name="dsack_1_free"/>
      <inertial pos="0 0 0" mass="0.02" diaginertia="0.0002 0.0002 0.0002"/>
      <flexcomp name="dsack_1_flex" type="mesh" file="../../object/sack10.obj" dim="2" mass="0.5275" radius="0.00433">
        <edge damping="0.18"/>
        <contact condim="4" friction="1.4 0.05 0.01" solref="0.004 1" solimp="0.95 0.99 0.002"/>
      </flexcomp>
      
      <body name="dsack_1_payload0" pos="0.000 0.000 0.010">
        <joint name="dsack_1_payload0_x" type="slide" axis="1 0 0" limited="true" range="-0.020 0.020" damping="4"/>
        <joint name="dsack_1_payload0_y" type="slide" axis="0 1 0" limited="true" range="-0.020 0.020" damping="4"/>
        <joint name="dsack_1_payload0_z" type="slide" axis="0 0 1" limited="true" range="-0.030 0.030" damping="4"/>
        <geom type="sphere" size="0.018" mass="0.0844" rgba="0.820 0.660 0.440 0.10" friction="0.9 0.03 0.01"/>
      </body>
      <body name="dsack_1_payload1" pos="0.022 0.000 -0.012">
        <joint name="dsack_1_payload1_x" type="slide" axis="1 0 0" limited="true" range="-0.020 0.020" damping="4"/>
        <joint name="dsack_1_payload1_y" type="slide" axis="0 1 0" limited="true" range="-0.020 0.020" damping="4"/>
        <joint name="dsack_1_payload1_z" type="slide" axis="0 0 1" limited="true" range="-0.030 0.030" damping="4"/>
        <geom type="sphere" size="0.016" mass="0.0739" rgba="0.820 0.660 0.440 0.10" friction="0.9 0.03 0.01"/>
      </body>
      <body name="dsack_1_payload2" pos="-0.020 0.010 0.000">
        <joint name="dsack_1_payload2_x" type="slide" axis="1 0 0" limited="true" range="-0.020 0.020" damping="4"/>
        <joint name="dsack_1_payload2_y" type="slide" axis="0 1 0" limited="true" range="-0.020 0.020" damping="4"/>
        <joint name="dsack_1_payload2_z" type="slide" axis="0 0 1" limited="true" range="-0.030 0.030" damping="4"/>
        <geom type="sphere" size="0.015" mass="0.0633" rgba="0.820 0.660 0.440 0.10" friction="0.9 0.03 0.01"/>
      </body>
      <site name="dsack_1_site" pos="0 0 0" size="0.006" rgba="0.820 0.660 0.440 1"/>
    </body>

    <body name="dsack_2" pos="0.7013 0.1847 0.2383" euler="-0.0987 0.1663 2.5950">
      <freejoint name="dsack_2_free"/>
      <inertial pos="0 0 0" mass="0.02" diaginertia="0.0002 0.0002 0.0002"/>
      <flexcomp name="dsack_2_flex" type="mesh" file="../../object/sack9.obj" dim="2" mass="0.7836" radius="0.00466">
        <edge damping="0.18"/>
        <contact condim="4" friction="1.4 0.05 0.01" solref="0.004 1" solimp="0.95 0.99 0.002"/>
      </flexcomp>
      
      <body name="dsack_2_payload0" pos="0.000 0.000 0.010">
        <joint name="dsack_2_payload0_x" type="slide" axis="1 0 0" limited="true" range="-0.020 0.020" damping="4"/>
        <joint name="dsack_2_payload0_y" type="slide" axis="0 1 0" limited="true" range="-0.020 0.020" damping="4"/>
        <joint name="dsack_2_payload0_z" type="slide" axis="0 0 1" limited="true" range="-0.030 0.030" damping="4"/>
        <geom type="sphere" size="0.018" mass="0.1254" rgba="0.760 0.600 0.400 0.10" friction="0.9 0.03 0.01"/>
      </body>
      <body name="dsack_2_payload1" pos="0.022 0.000 -0.012">
        <joint name="dsack_2_payload1_x" type="slide" axis="1 0 0" limited="true" range="-0.020 0.020" damping="4"/>
        <joint name="dsack_2_payload1_y" type="slide" axis="0 1 0" limited="true" range="-0.020 0.020" damping="4"/>
        <joint name="dsack_2_payload1_z" type="slide" axis="0 0 1" limited="true" range="-0.030 0.030" damping="4"/>
        <geom type="sphere" size="0.016" mass="0.1097" rgba="0.760 0.600 0.400 0.10" friction="0.9 0.03 0.01"/>
      </body>
      <body name="dsack_2_payload2" pos="-0.020 0.010 0.000">
        <joint name="dsack_2_payload2_x" type="slide" axis="1 0 0" limited="true" range="-0.020 0.020" damping="4"/>
        <joint name="dsack_2_payload2_y" type="slide" axis="0 1 0" limited="true" range="-0.020 0.020" damping="4"/>
        <joint name="dsack_2_payload2_z" type="slide" axis="0 0 1" limited="true" range="-0.030 0.030" damping="4"/>
        <geom type="sphere" size="0.015" mass="0.0940" rgba="0.760 0.600 0.400 0.10" friction="0.9 0.03 0.01"/>
      </body>
      <site name="dsack_2_site" pos="0 0 0" size="0.006" rgba="0.760 0.600 0.400 1"/>
    </body>
  </worldbody>
</mujoco>
