<mujoco model="top_grasp_flat_scoop_drag_seed7">
  <compiler angle="radian" coordinate="local" inertiafromgeom="true" meshdir="D:/Michael/2025/01.Research/01.Parceldetection/16.Pybullet/bullet3-master (1)/bullet3-master/examples/pybullet/examples/DeformableTest/Sackcodex2/object"/>
  <option timestep="0.002" gravity="0 0 -9.81" integrator="implicitfast" iterations="100" tolerance="1e-8"/>
  <size memory="768M" nconmax="12000"/>

  <visual>
    <global azimuth="128" elevation="-20"/>
    <headlight ambient="0.34 0.34 0.34" diffuse="0.78 0.78 0.78" specular="0.15 0.15 0.15"/>
    <rgba haze="0.11 0.13 0.18 1"/>
  </visual>

  <default>
    <geom condim="4" friction="1.15 0.03 0.01" margin="0.003" solimp="0.93 0.98 0.003" solref="0.012 1"/>
    <joint damping="1.2" armature="0.002"/>
    <position kp="2500" forcelimited="true" forcerange="-420 420"/>
    <motor ctrllimited="true"/>
  </default>

  <asset>
    <mesh name="sack_0_visual_mesh" file="sack3.obj" scale="0.0733 0.0733 0.0769"/>
    <mesh name="sack_1_visual_mesh" file="sack10.obj" scale="0.0653 0.0653 0.0664"/>
    <mesh name="sack_2_visual_mesh" file="sack7.obj" scale="0.0714 0.0714 0.0782"/>
    <mesh name="sack_3_visual_mesh" file="sack10.obj" scale="0.0725 0.0725 0.0756"/>
    <mesh name="sack_4_visual_mesh" file="sack9.obj" scale="0.0682 0.0682 0.0726"/>
  </asset>

  <worldbody>
    <light name="key" pos="0.85 0.15 1.8" dir="-0.2 -0.1 -1" directional="true"/>
    <geom name="floor" type="plane" size="2 2 0.1" rgba="0.93 0.93 0.93 1"/>
    <geom name="work_pad" type="box" pos="0.62 0 0.012" size="0.30 0.30 0.012" rgba="0.60 0.61 0.62 1" friction="1.4 0.05 0.01"/>
    <geom name="corral_front" type="box" pos="0.93 0.00 0.08" size="0.010 0.30 0.08" rgba="0.55 0.55 0.58 0.22" friction="1.0 0.03 0.01"/>
    <geom name="corral_back" type="box" pos="0.31 0.00 0.08" size="0.010 0.30 0.08" rgba="0.55 0.55 0.58 0.18" friction="1.0 0.03 0.01"/>
    <geom name="corral_left" type="box" pos="0.62 0.30 0.08" size="0.30 0.010 0.08" rgba="0.55 0.55 0.58 0.14" friction="1.0 0.03 0.01"/>
    <geom name="corral_right" type="box" pos="0.62 -0.30 0.08" size="0.30 0.010 0.08" rgba="0.55 0.55 0.58 0.14" friction="1.0 0.03 0.01"/>
    <camera name="overview" pos="1.22 0.00 0.92" xyaxes="0 1 0 -0.46 0 0.88"/>

    <body name="gripper_mocap" mocap="true" pos="0.36 -0.33 0.30" quat="0.707107 0 -0.707107 0"/>
    <body name="scoop_mocap" mocap="true" pos="0.42 0.28 0.20" quat="1 0 0 0"/>

    <body name="gripper_tool" pos="0.36 -0.33 0.30" quat="0.707107 0 -0.707107 0">
      <freejoint name="gripper_tool_free"/>
      <inertial pos="0 0 0.04" mass="0.08" diaginertia="0.0002 0.0002 0.0002"/>
      <geom name="gripper_palm" type="box" pos="0 0 0.030" size="0.020 0.026 0.030" rgba="0.14 0.14 0.14 1"/>
      <body name="left_finger_body" pos="0 0 0.072">
        <joint name="left_finger_slide" type="slide" axis="0 1 0" limited="true" range="0.010 0.040" damping="12"/>
        <geom name="left_finger_geom" type="box" pos="0 0.020 0" size="0.012 0.006 0.040" rgba="0.10 0.10 0.10 1" friction="2.2 0.05 0.01"/>
      </body>
      <body name="right_finger_body" pos="0 0 0.072">
        <joint name="right_finger_slide" type="slide" axis="0 -1 0" limited="true" range="0.010 0.040" damping="12"/>
        <geom name="right_finger_geom" type="box" pos="0 -0.020 0" size="0.012 0.006 0.040" rgba="0.10 0.10 0.10 1" friction="2.2 0.05 0.01"/>
      </body>
      <site name="gripper_pinch_site" pos="0 0 0.074" size="0.006" rgba="1 0 0 1"/>
    </body>

    <body name="scoop_tool" pos="0.42 0.28 0.20" quat="1 0 0 0">
      <freejoint name="scoop_tool_free"/>
      <inertial pos="0 0 0.02" mass="0.10" diaginertia="0.0003 0.0003 0.0003"/>
      <geom name="scoop_plate" type="box" pos="0.062 0 0" size="0.062 0.085 0.004" rgba="0.28 0.31 0.35 1" friction="1.7 0.05 0.01"/>
      <geom name="scoop_lip" type="box" pos="0.126 0 0.014" size="0.004 0.085 0.014" rgba="0.24 0.27 0.30 1" friction="1.7 0.05 0.01"/>
      <geom name="scoop_left_rail" type="box" pos="0.062 0.082 0.018" size="0.056 0.004 0.018" rgba="0.24 0.27 0.30 1"/>
      <geom name="scoop_right_rail" type="box" pos="0.062 -0.082 0.018" size="0.056 0.004 0.018" rgba="0.24 0.27 0.30 1"/>
      <geom name="scoop_backstop" type="box" pos="0.000 0 0.022" size="0.006 0.082 0.022" rgba="0.24 0.27 0.30 1"/>
      <site name="scoop_tip_site" pos="0.126 0 0.005" size="0.005" rgba="0 0 1 1"/>
      <site name="scoop_center_site" pos="0.060 0 0.020" size="0.005" rgba="0 0.7 1 1"/>
      <site name="score_overlay_site" pos="0.030 0 0.080" size="0.008" rgba="0 1 0 0.8"/>
    </body>


    <body name="sack_0" pos="0.4878 -0.0647 0.1211" euler="-0.2349 0.0038 -0.8439">
      <freejoint name="sack_0_free"/>

      <geom name="sack_0_visual" type="mesh" mesh="sack_0_visual_mesh" rgba="0.760 0.600 0.400 0.92" contype="0" conaffinity="0"/>
      <site name="sack_0_center_site" pos="0 0 0.000" size="0.006" rgba="0 1 0 1"/>
      <site name="sack_0_top_site" pos="0 -0.0060 0.1222" size="0.007" rgba="1 0.5 0 1"/>
      <site name="sack_0_side_site" pos="0.0000 -0.0566 0.018" size="0.007" rgba="1 0.8 0 1"/>

      <geom name="sack_0_core_geom" type="ellipsoid" pos="0 0 0.0059" size="0.0446 0.0348 0.0783" mass="0.9274" rgba="0.760 0.600 0.400 0.12" friction="1.0 0.03 0.01"/>
      <geom name="sack_0_core_front" type="capsule" fromto="-0.0200 0 -0.0200 0.0450 0 0.0600" size="0.0303" mass="0.2208" rgba="0.760 0.600 0.400 0.10"/>
      <geom name="sack_0_core_left" type="capsule" fromto="-0.008 0.0350 -0.010 0.018 0.0530 0.060" size="0.0241" mass="0.3975" rgba="0.760 0.600 0.400 0.10"/>
      <geom name="sack_0_core_right" type="capsule" fromto="-0.006 -0.0350 -0.008 0.020 -0.0550 0.054" size="0.0222" mass="0.3975" rgba="0.760 0.600 0.400 0.10"/>

      <body name="sack_0_bottom_skin" pos="0 0.0027 -0.1016">
        <joint name="sack_0_bottom_x" type="slide" axis="1 0 0" limited="true" range="-0.012 0.012" damping="18" stiffness="469.4"/>
        <joint name="sack_0_bottom_y" type="slide" axis="0 1 0" limited="true" range="-0.012 0.012" damping="18" stiffness="469.4"/>
        <joint name="sack_0_bottom_z" type="slide" axis="0 0 1" limited="true" range="-0.008 0.020" damping="24" stiffness="578.2"/>
        <geom name="sack_0_bottom_support" type="box" size="0.0753 0.0626 0.0100" mass="0.1766" rgba="0.760 0.600 0.400 0.34" friction="1.55 0.05 0.01"/>
      </body>

      <body name="sack_0_top_skin" pos="0.0000 -0.0060 0.0922">
        <joint name="sack_0_top_x" type="slide" axis="1 0 0" limited="true" range="-0.018 0.018" damping="12" stiffness="180.3"/>
        <joint name="sack_0_top_y" type="slide" axis="0 1 0" limited="true" range="-0.018 0.018" damping="12" stiffness="180.3"/>
        <joint name="sack_0_top_z" type="slide" axis="0 0 1" limited="true" range="-0.040 0.010" damping="14" stiffness="133.1"/>
        <geom name="sack_0_top_grip" type="box" size="0.0593 0.0466 0.0150" mass="0.1325" rgba="0.760 0.600 0.400 0.26" friction="2.2 0.05 0.01"/>
      </body>

      <body name="sack_0_left_skin" pos="0 0.0816 0.010">
        <joint name="sack_0_left_side_slide" type="slide" axis="0 -1 0" limited="true" range="-0.028 0.016" damping="16" stiffness="235.8"/>
        <geom name="sack_0_side_left" type="box" size="0.0713 0.0090 0.0996" mass="0.1325" rgba="0.760 0.600 0.400 0.24"/>
      </body>

      <body name="sack_0_right_skin" pos="0 -0.0776 0.010">
        <joint name="sack_0_right_side_slide" type="slide" axis="0 1 0" limited="true" range="-0.028 0.016" damping="16" stiffness="218.6"/>
        <geom name="sack_0_side_right" type="box" size="0.0713 0.0090 0.0996" mass="0.1325" rgba="0.760 0.600 0.400 0.24"/>
      </body>

      <body name="sack_0_front_skin" pos="0.0653 0 0.000">
        <joint name="sack_0_front_slide" type="slide" axis="-1 0 0" limited="true" range="-0.022 0.012" damping="15" stiffness="224.7"/>
        <geom name="sack_0_front_panel" type="box" size="0.0090 0.0626 0.0976" mass="0.1104" rgba="0.760 0.600 0.400 0.22"/>
      </body>

      <body name="sack_0_back_skin" pos="-0.0653 0 0.000">
        <joint name="sack_0_back_slide" type="slide" axis="1 0 0" limited="true" range="-0.022 0.012" damping="15" stiffness="207.5"/>
        <geom name="sack_0_back_panel" type="box" size="0.0090 0.0626 0.0976" mass="0.1104" rgba="0.760 0.600 0.400 0.22"/>
      </body>

      <body name="sack_0_local_patch" pos="0.0000 -0.0270 0.0369">
        <joint name="sack_0_bulge_y" type="slide" axis="0 1 0" limited="true" range="-0.020 0.020" damping="8" stiffness="93.7"/>
        <joint name="sack_0_bulge_z" type="slide" axis="0 0 1" limited="true" range="-0.014 0.028" damping="8" stiffness="95.3"/>
        <geom name="sack_0_compliant_patch" type="ellipsoid" size="0.0201 0.0163 0.0261" mass="0.0883" rgba="0.760 0.600 0.400 0.28"/>
      </body>
    </body>

    <body name="sack_1" pos="0.6130 -0.0383 0.1090" euler="0.0347 0.0409 -0.5081">
      <freejoint name="sack_1_free"/>

      <geom name="sack_1_visual" type="mesh" mesh="sack_1_visual_mesh" rgba="0.820 0.670 0.440 0.92" contype="0" conaffinity="0"/>
      <site name="sack_1_center_site" pos="0 0 0.000" size="0.006" rgba="0 1 0 1"/>
      <site name="sack_1_top_site" pos="0 0.0060 0.0917" size="0.007" rgba="1 0.5 0 1"/>
      <site name="sack_1_side_site" pos="0.0140 0.0468 0.018" size="0.007" rgba="1 0.8 0 1"/>

      <geom name="sack_1_core_geom" type="ellipsoid" pos="0 0 0.0056" size="0.0448 0.0345 0.0662" mass="0.6399" rgba="0.820 0.670 0.440 0.12" friction="1.0 0.03 0.01"/>
      <geom name="sack_1_core_front" type="capsule" fromto="-0.0060 0 -0.0200 0.0590 0 0.0600" size="0.0292" mass="0.1524" rgba="0.820 0.670 0.440 0.10"/>
      <geom name="sack_1_core_left" type="capsule" fromto="-0.008 0.0230 -0.010 0.018 0.0410 0.060" size="0.0240" mass="0.2742" rgba="0.820 0.670 0.440 0.10"/>
      <geom name="sack_1_core_right" type="capsule" fromto="-0.006 -0.0230 -0.008 0.020 -0.0430 0.054" size="0.0220" mass="0.2742" rgba="0.820 0.670 0.440 0.10"/>

      <body name="sack_1_bottom_skin" pos="0 -0.0023 -0.0816">
        <joint name="sack_1_bottom_x" type="slide" axis="1 0 0" limited="true" range="-0.012 0.012" damping="18" stiffness="435.9"/>
        <joint name="sack_1_bottom_y" type="slide" axis="0 1 0" limited="true" range="-0.012 0.012" damping="18" stiffness="435.9"/>
        <joint name="sack_1_bottom_z" type="slide" axis="0 0 1" limited="true" range="-0.008 0.020" damping="24" stiffness="537.2"/>
        <geom name="sack_1_bottom_support" type="box" size="0.0722 0.0528 0.0100" mass="0.1219" rgba="0.820 0.670 0.440 0.34" friction="1.55 0.05 0.01"/>
      </body>

      <body name="sack_1_top_skin" pos="0.0140 0.0060 0.0617">
        <joint name="sack_1_top_x" type="slide" axis="1 0 0" limited="true" range="-0.018 0.018" damping="12" stiffness="167.3"/>
        <joint name="sack_1_top_y" type="slide" axis="0 1 0" limited="true" range="-0.018 0.018" damping="12" stiffness="167.3"/>
        <joint name="sack_1_top_z" type="slide" axis="0 0 1" limited="true" range="-0.040 0.010" damping="14" stiffness="122.0"/>
        <geom name="sack_1_top_grip" type="box" size="0.0562 0.0368 0.0150" mass="0.0914" rgba="0.820 0.670 0.440 0.26" friction="2.2 0.05 0.01"/>
      </body>

      <body name="sack_1_left_skin" pos="0 0.0598 0.010">
        <joint name="sack_1_left_side_slide" type="slide" axis="0 -1 0" limited="true" range="-0.028 0.016" damping="16" stiffness="212.6"/>
        <geom name="sack_1_side_left" type="box" size="0.0682 0.0090 0.0796" mass="0.0914" rgba="0.820 0.670 0.440 0.24"/>
      </body>

      <body name="sack_1_right_skin" pos="0 -0.0558 0.010">
        <joint name="sack_1_right_side_slide" type="slide" axis="0 1 0" limited="true" range="-0.028 0.016" damping="16" stiffness="197.3"/>
        <geom name="sack_1_side_right" type="box" size="0.0682 0.0090 0.0796" mass="0.0914" rgba="0.820 0.670 0.440 0.24"/>
      </body>

      <body name="sack_1_front_skin" pos="0.0762 0 0.000">
        <joint name="sack_1_front_slide" type="slide" axis="-1 0 0" limited="true" range="-0.022 0.012" damping="15" stiffness="207.9"/>
        <geom name="sack_1_front_panel" type="box" size="0.0090 0.0528 0.0776" mass="0.0762" rgba="0.820 0.670 0.440 0.22"/>
      </body>

      <body name="sack_1_back_skin" pos="-0.0622 0 0.000">
        <joint name="sack_1_back_slide" type="slide" axis="1 0 0" limited="true" range="-0.022 0.012" damping="15" stiffness="192.6"/>
        <geom name="sack_1_back_panel" type="box" size="0.0090 0.0528 0.0776" mass="0.0762" rgba="0.820 0.670 0.440 0.22"/>
      </body>

      <body name="sack_1_local_patch" pos="0.0084 0.0150 0.0480">
        <joint name="sack_1_bulge_y" type="slide" axis="0 1 0" limited="true" range="-0.020 0.020" damping="8" stiffness="116.1"/>
        <joint name="sack_1_bulge_z" type="slide" axis="0 0 1" limited="true" range="-0.014 0.028" damping="8" stiffness="112.1"/>
        <geom name="sack_1_compliant_patch" type="ellipsoid" size="0.0200 0.0161 0.0263" mass="0.0609" rgba="0.820 0.670 0.440 0.28"/>
      </body>
    </body>

    <body name="sack_2" pos="0.6943 0.0443 0.1140" euler="0.0345 -0.1187 1.8496">
      <freejoint name="sack_2_free"/>

      <geom name="sack_2_visual" type="mesh" mesh="sack_2_visual_mesh" rgba="0.840 0.740 0.480 0.92" contype="0" conaffinity="0"/>
      <site name="sack_2_center_site" pos="0 0 0.000" size="0.006" rgba="0 1 0 1"/>
      <site name="sack_2_top_site" pos="0 0.0060 0.1391" size="0.007" rgba="1 0.5 0 1"/>
      <site name="sack_2_side_site" pos="0.0140 0.0512 0.018" size="0.007" rgba="1 0.8 0 1"/>

      <geom name="sack_2_core_geom" type="ellipsoid" pos="0 0 0.0059" size="0.0508 0.0429 0.0908" mass="1.0076" rgba="0.840 0.740 0.480 0.12" friction="1.0 0.03 0.01"/>
      <geom name="sack_2_core_front" type="capsule" fromto="-0.0060 0 -0.0200 0.0590 0 0.0600" size="0.0318" mass="0.2399" rgba="0.840 0.740 0.480 0.10"/>
      <geom name="sack_2_core_left" type="capsule" fromto="-0.008 0.0288 -0.010 0.018 0.0468 0.060" size="0.0241" mass="0.4318" rgba="0.840 0.740 0.480 0.10"/>
      <geom name="sack_2_core_right" type="capsule" fromto="-0.006 -0.0288 -0.008 0.020 -0.0488 0.054" size="0.0221" mass="0.4318" rgba="0.840 0.740 0.480 0.10"/>

      <body name="sack_2_bottom_skin" pos="0 0.0139 -0.0879">
        <joint name="sack_2_bottom_x" type="slide" axis="1 0 0" limited="true" range="-0.012 0.012" damping="18" stiffness="514.2"/>
        <joint name="sack_2_bottom_y" type="slide" axis="0 1 0" limited="true" range="-0.012 0.012" damping="18" stiffness="514.2"/>
        <joint name="sack_2_bottom_z" type="slide" axis="0 0 1" limited="true" range="-0.008 0.020" damping="24" stiffness="633.0"/>
        <geom name="sack_2_bottom_support" type="box" size="0.0726 0.0572 0.0100" mass="0.1919" rgba="0.840 0.740 0.480 0.34" friction="1.55 0.05 0.01"/>
      </body>

      <body name="sack_2_top_skin" pos="0.0140 0.0060 0.1091">
        <joint name="sack_2_top_x" type="slide" axis="1 0 0" limited="true" range="-0.018 0.018" damping="12" stiffness="197.8"/>
        <joint name="sack_2_top_y" type="slide" axis="0 1 0" limited="true" range="-0.018 0.018" damping="12" stiffness="197.8"/>
        <joint name="sack_2_top_z" type="slide" axis="0 0 1" limited="true" range="-0.040 0.010" damping="14" stiffness="148.1"/>
        <geom name="sack_2_top_grip" type="box" size="0.0566 0.0412 0.0150" mass="0.1439" rgba="0.840 0.740 0.480 0.26" friction="2.2 0.05 0.01"/>
      </body>

      <body name="sack_2_left_skin" pos="0 0.0699 0.010">
        <joint name="sack_2_left_side_slide" type="slide" axis="0 -1 0" limited="true" range="-0.028 0.016" damping="16" stiffness="266.0"/>
        <geom name="sack_2_side_left" type="box" size="0.0686 0.0090 0.0859" mass="0.1439" rgba="0.840 0.740 0.480 0.24"/>
      </body>

      <body name="sack_2_right_skin" pos="0 -0.0659 0.010">
        <joint name="sack_2_right_side_slide" type="slide" axis="0 1 0" limited="true" range="-0.028 0.016" damping="16" stiffness="246.3"/>
        <geom name="sack_2_side_right" type="box" size="0.0686 0.0090 0.0859" mass="0.1439" rgba="0.840 0.740 0.480 0.24"/>
      </body>

      <body name="sack_2_front_skin" pos="0.0766 0 0.000">
        <joint name="sack_2_front_slide" type="slide" axis="-1 0 0" limited="true" range="-0.022 0.012" damping="15" stiffness="247.1"/>
        <geom name="sack_2_front_panel" type="box" size="0.0090 0.0572 0.0839" mass="0.1199" rgba="0.840 0.740 0.480 0.22"/>
      </body>

      <body name="sack_2_back_skin" pos="-0.0626 0 0.000">
        <joint name="sack_2_back_slide" type="slide" axis="1 0 0" limited="true" range="-0.022 0.012" damping="15" stiffness="227.4"/>
        <geom name="sack_2_back_panel" type="box" size="0.0090 0.0572 0.0839" mass="0.1199" rgba="0.840 0.740 0.480 0.22"/>
      </body>

      <body name="sack_2_local_patch" pos="0.0084 0.0208 0.0219">
        <joint name="sack_2_bulge_y" type="slide" axis="0 1 0" limited="true" range="-0.020 0.020" damping="8" stiffness="63.8"/>
        <joint name="sack_2_bulge_z" type="slide" axis="0 0 1" limited="true" range="-0.014 0.028" damping="8" stiffness="72.9"/>
        <geom name="sack_2_compliant_patch" type="ellipsoid" size="0.0201 0.0162 0.0260" mass="0.0960" rgba="0.840 0.740 0.480 0.28"/>
      </body>
    </body>

    <body name="sack_3" pos="0.6931 -0.1727 0.1228" euler="0.2412 0.1844 0.5020">
      <freejoint name="sack_3_free"/>

      <geom name="sack_3_visual" type="mesh" mesh="sack_3_visual_mesh" rgba="0.820 0.670 0.440 0.92" contype="0" conaffinity="0"/>
      <site name="sack_3_center_site" pos="0 0 0.000" size="0.006" rgba="0 1 0 1"/>
      <site name="sack_3_top_site" pos="0 -0.0060 0.1026" size="0.007" rgba="1 0.5 0 1"/>
      <site name="sack_3_side_site" pos="0.0000 -0.0491 0.018" size="0.007" rgba="1 0.8 0 1"/>

      <geom name="sack_3_core_geom" type="ellipsoid" pos="0 0 0.0057" size="0.0454 0.0355 0.0677" mass="0.6597" rgba="0.820 0.670 0.440 0.12" friction="1.0 0.03 0.01"/>
      <geom name="sack_3_core_front" type="capsule" fromto="-0.0200 0 -0.0200 0.0450 0 0.0600" size="0.0301" mass="0.1571" rgba="0.820 0.670 0.440 0.10"/>
      <geom name="sack_3_core_left" type="capsule" fromto="-0.008 0.0286 -0.010 0.018 0.0466 0.060" size="0.0241" mass="0.2827" rgba="0.820 0.670 0.440 0.10"/>
      <geom name="sack_3_core_right" type="capsule" fromto="-0.006 -0.0286 -0.008 0.020 -0.0486 0.054" size="0.0221" mass="0.2827" rgba="0.820 0.670 0.440 0.10"/>

      <body name="sack_3_bottom_skin" pos="0 0.0054 -0.0998">
        <joint name="sack_3_bottom_x" type="slide" axis="1 0 0" limited="true" range="-0.012 0.012" damping="18" stiffness="461.8"/>
        <joint name="sack_3_bottom_y" type="slide" axis="0 1 0" limited="true" range="-0.012 0.012" damping="18" stiffness="461.8"/>
        <joint name="sack_3_bottom_z" type="slide" axis="0 0 1" limited="true" range="-0.008 0.020" damping="24" stiffness="568.8"/>
        <geom name="sack_3_bottom_support" type="box" size="0.0730 0.0551 0.0100" mass="0.1257" rgba="0.820 0.670 0.440 0.34" friction="1.55 0.05 0.01"/>
      </body>

      <body name="sack_3_top_skin" pos="0.0000 -0.0060 0.0726">
        <joint name="sack_3_top_x" type="slide" axis="1 0 0" limited="true" range="-0.018 0.018" damping="12" stiffness="177.3"/>
        <joint name="sack_3_top_y" type="slide" axis="0 1 0" limited="true" range="-0.018 0.018" damping="12" stiffness="177.3"/>
        <joint name="sack_3_top_z" type="slide" axis="0 0 1" limited="true" range="-0.040 0.010" damping="14" stiffness="130.6"/>
        <geom name="sack_3_top_grip" type="box" size="0.0570 0.0391 0.0150" mass="0.0942" rgba="0.820 0.670 0.440 0.26" friction="2.2 0.05 0.01"/>
      </body>

      <body name="sack_3_left_skin" pos="0 0.0677 0.010">
        <joint name="sack_3_left_side_slide" type="slide" axis="0 -1 0" limited="true" range="-0.028 0.016" damping="16" stiffness="230.0"/>
        <geom name="sack_3_side_left" type="box" size="0.0690 0.0090 0.0978" mass="0.0942" rgba="0.820 0.670 0.440 0.24"/>
      </body>

      <body name="sack_3_right_skin" pos="0 -0.0637 0.010">
        <joint name="sack_3_right_side_slide" type="slide" axis="0 1 0" limited="true" range="-0.028 0.016" damping="16" stiffness="213.3"/>
        <geom name="sack_3_side_right" type="box" size="0.0690 0.0090 0.0978" mass="0.0942" rgba="0.820 0.670 0.440 0.24"/>
      </body>

      <body name="sack_3_front_skin" pos="0.0630 0 0.000">
        <joint name="sack_3_front_slide" type="slide" axis="-1 0 0" limited="true" range="-0.022 0.012" damping="15" stiffness="220.9"/>
        <geom name="sack_3_front_panel" type="box" size="0.0090 0.0551 0.0958" mass="0.0785" rgba="0.820 0.670 0.440 0.22"/>
      </body>

      <body name="sack_3_back_skin" pos="-0.0630 0 0.000">
        <joint name="sack_3_back_slide" type="slide" axis="1 0 0" limited="true" range="-0.022 0.012" damping="15" stiffness="204.1"/>
        <geom name="sack_3_back_panel" type="box" size="0.0090 0.0551 0.0958" mass="0.0785" rgba="0.820 0.670 0.440 0.22"/>
      </body>

      <body name="sack_3_local_patch" pos="0.0000 -0.0206 0.0394">
        <joint name="sack_3_bulge_y" type="slide" axis="0 1 0" limited="true" range="-0.020 0.020" damping="8" stiffness="98.8"/>
        <joint name="sack_3_bulge_z" type="slide" axis="0 0 1" limited="true" range="-0.014 0.028" damping="8" stiffness="99.1"/>
        <geom name="sack_3_compliant_patch" type="ellipsoid" size="0.0201 0.0162 0.0263" mass="0.0628" rgba="0.820 0.670 0.440 0.28"/>
      </body>
    </body>

    <body name="sack_4" pos="0.8150 -0.0043 0.1470" euler="0.1699 0.0463 -1.3959">
      <freejoint name="sack_4_free"/>

      <geom name="sack_4_visual" type="mesh" mesh="sack_4_visual_mesh" rgba="0.840 0.740 0.480 0.92" contype="0" conaffinity="0"/>
      <site name="sack_4_center_site" pos="0 0 0.000" size="0.006" rgba="0 1 0 1"/>
      <site name="sack_4_top_site" pos="0 0.0060 0.1309" size="0.007" rgba="1 0.5 0 1"/>
      <site name="sack_4_side_site" pos="0.0000 0.0485 0.018" size="0.007" rgba="1 0.8 0 1"/>

      <geom name="sack_4_core_geom" type="ellipsoid" pos="0 0 0.0059" size="0.0500 0.0416 0.0885" mass="1.0882" rgba="0.840 0.740 0.480 0.12" friction="1.0 0.03 0.01"/>
      <geom name="sack_4_core_front" type="capsule" fromto="-0.0200 0 -0.0200 0.0450 0 0.0600" size="0.0308" mass="0.2591" rgba="0.840 0.740 0.480 0.10"/>
      <geom name="sack_4_core_left" type="capsule" fromto="-0.008 0.0238 -0.010 0.018 0.0418 0.060" size="0.0240" mass="0.4664" rgba="0.840 0.740 0.480 0.10"/>
      <geom name="sack_4_core_right" type="capsule" fromto="-0.006 -0.0238 -0.008 0.020 -0.0438 0.054" size="0.0220" mass="0.4664" rgba="0.840 0.740 0.480 0.10"/>

      <body name="sack_4_bottom_skin" pos="0 -0.0076 -0.0693">
        <joint name="sack_4_bottom_x" type="slide" axis="1 0 0" limited="true" range="-0.012 0.012" damping="18" stiffness="483.7"/>
        <joint name="sack_4_bottom_y" type="slide" axis="0 1 0" limited="true" range="-0.012 0.012" damping="18" stiffness="483.7"/>
        <joint name="sack_4_bottom_z" type="slide" axis="0 0 1" limited="true" range="-0.008 0.020" damping="24" stiffness="595.7"/>
        <geom name="sack_4_bottom_support" type="box" size="0.0717 0.0545 0.0100" mass="0.2073" rgba="0.840 0.740 0.480 0.34" friction="1.55 0.05 0.01"/>
      </body>

      <body name="sack_4_top_skin" pos="0.0000 0.0060 0.1009">
        <joint name="sack_4_top_x" type="slide" axis="1 0 0" limited="true" range="-0.018 0.018" damping="12" stiffness="185.9"/>
        <joint name="sack_4_top_y" type="slide" axis="0 1 0" limited="true" range="-0.018 0.018" damping="12" stiffness="185.9"/>
        <joint name="sack_4_top_z" type="slide" axis="0 0 1" limited="true" range="-0.040 0.010" damping="14" stiffness="137.9"/>
        <geom name="sack_4_top_grip" type="box" size="0.0557 0.0385 0.0150" mass="0.1555" rgba="0.840 0.740 0.480 0.26" friction="2.2 0.05 0.01"/>
      </body>

      <body name="sack_4_left_skin" pos="0 0.0623 0.010">
        <joint name="sack_4_left_side_slide" type="slide" axis="0 -1 0" limited="true" range="-0.028 0.016" damping="16" stiffness="245.6"/>
        <geom name="sack_4_side_left" type="box" size="0.0677 0.0090 0.0673" mass="0.1555" rgba="0.840 0.740 0.480 0.24"/>
      </body>

      <body name="sack_4_right_skin" pos="0 -0.0583 0.010">
        <joint name="sack_4_right_side_slide" type="slide" axis="0 1 0" limited="true" range="-0.028 0.016" damping="16" stiffness="227.6"/>
        <geom name="sack_4_side_right" type="box" size="0.0677 0.0090 0.0673" mass="0.1555" rgba="0.840 0.740 0.480 0.24"/>
      </body>

      <body name="sack_4_front_skin" pos="0.0617 0 0.000">
        <joint name="sack_4_front_slide" type="slide" axis="-1 0 0" limited="true" range="-0.022 0.012" damping="15" stiffness="231.9"/>
        <geom name="sack_4_front_panel" type="box" size="0.0090 0.0545 0.0653" mass="0.1295" rgba="0.840 0.740 0.480 0.22"/>
      </body>

      <body name="sack_4_back_skin" pos="-0.0617 0 0.000">
        <joint name="sack_4_back_slide" type="slide" axis="1 0 0" limited="true" range="-0.022 0.012" damping="15" stiffness="213.9"/>
        <geom name="sack_4_back_panel" type="box" size="0.0090 0.0545 0.0653" mass="0.1295" rgba="0.840 0.740 0.480 0.22"/>
      </body>

      <body name="sack_4_local_patch" pos="0.0000 0.0158 0.0321">
        <joint name="sack_4_bulge_y" type="slide" axis="0 1 0" limited="true" range="-0.020 0.020" damping="8" stiffness="84.2"/>
        <joint name="sack_4_bulge_z" type="slide" axis="0 0 1" limited="true" range="-0.014 0.028" damping="8" stiffness="88.1"/>
        <geom name="sack_4_compliant_patch" type="ellipsoid" size="0.0200 0.0161 0.0261" mass="0.1036" rgba="0.840 0.740 0.480 0.28"/>
      </body>
    </body>
  </worldbody>

  <equality>
    <weld name="gripper_follow" body1="gripper_mocap" body2="gripper_tool" torquescale="400" solref="0.002 1" solimp="0.99 0.999 0.0001"/>
    <weld name="scoop_follow" body1="scoop_mocap" body2="scoop_tool" torquescale="500" solref="0.002 1" solimp="0.99 0.999 0.0001"/>
  </equality>

  <actuator>
    <position name="left_finger_act" joint="left_finger_slide" ctrlrange="0.010 0.040" kp="2800" forcerange="-220 220"/>
    <position name="right_finger_act" joint="right_finger_slide" ctrlrange="0.010 0.040" kp="2800" forcerange="-220 220"/>
  </actuator>

  <contact>
    <exclude body1="sack_0_top_skin" body2="sack_0_left_skin"/>
    <exclude body1="sack_0_top_skin" body2="sack_0_right_skin"/>
    <exclude body1="sack_1_top_skin" body2="sack_1_left_skin"/>
    <exclude body1="sack_1_top_skin" body2="sack_1_right_skin"/>
    <exclude body1="sack_2_top_skin" body2="sack_2_left_skin"/>
    <exclude body1="sack_2_top_skin" body2="sack_2_right_skin"/>
    <exclude body1="sack_3_top_skin" body2="sack_3_left_skin"/>
    <exclude body1="sack_3_top_skin" body2="sack_3_right_skin"/>
    <exclude body1="sack_4_top_skin" body2="sack_4_left_skin"/>
    <exclude body1="sack_4_top_skin" body2="sack_4_right_skin"/>
  </contact>
</mujoco>
